<?xml version="1.0"?>
<mujoco model="robot">
    <compiler angle="degree"/>

    <default>
        <joint armature="0.1" damping="1.0" limited="true" margin="0.01"/>
    </default>

    <option timestep="0.001" integrator="RK4" gravity="0 0 -9.81" iterations="50"/>

    <worldbody>
        <body name="base" pos="0 0 0">
            <geom name="base_geom" type="box" size="0.4 0.4 0.4"/>
            <body name="body1" pos="0 0 0.2">
                <joint name="joint1" type="hinge" axis="0 0 1" pos="0 0 0" range="-180 180" damping="0.05"/>
                <geom name="body1_geom" type="box" size="0.2 0.2 0.2"/>
                <body name="body2" pos="0.2 0 0">
                    <joint name="joint2" type="hinge" axis="1 0 0" pos="0 0 0" range="-180 180" damping="0.05"/>
                    <geom name="body2_geom" type="box" size="0.2 0.2 0.2" />
                    <body name="body3" pos="0.2 0 0">
                        <joint name="joint3" type="hinge" axis="1 0 0" pos="0 0 0" range="-180 180" damping="0.05"/>
                        <geom name="body3_geom" type="box" size="0.2 0.2 0.2"/>
                        <body name="end_effector" pos="0.2 0 0">
                            <geom name="ee_geom" type="sphere" size="0.05"/>
                        </body>
                    </body>
                </body>
            </body>
        </body>
    </worldbody>

    <actuator>
        <motor name="motor1" joint="joint1" ctrlrange="-2 2"/>
        <motor name="motor2" joint="joint2" ctrlrange="-2 2"/>
        <motor name="motor3" joint="joint3" ctrlrange="-2 2"/>
    </actuator>

    <visual>
        <map fogstart="5" fogend="40" force="0.1"/>
        <headlight ambient="0.4 0.4 0.4" diffuse="0.8 0.8 0.8" specular="0.2 0.2 0.2"/>
    </visual>

    <!-- <material name="grey" rgba="0.5 0.5 0.5 1"/>
    <material name="green" rgba="0 1 0 1"/>
    <material name="red" rgba="1 0 0 1"/>
    <material name="blue" rgba="0 0 1 1"/>
    <material name="orange" rgba="1 0.5 0 1"/> -->
</mujoco>
